Workbook

Sheet Monthly Report
B1: Monthly Bookkeeping Report: September 2026
B2: SAMPLE DATA: fictional business and figures, for demonstration only. Not a real client.
B3: Client: "Sample Rentals & Bar" (fictional) | Prepared by Caristo Mulenga, CayTech Digital Solutions | 30 Sep 2026
B4: Basis: management report, earned basis (see Basis and assumptions below). Not an audit.
B6: 1. Profit for the month | C6: Sep 2026 | D6: Aug 2026 | E6: Change
B7: Rent due | C7: ='Rent Roll'!D11 -> 5400 | D7: 5400 | E7: =C7-D7 -> 0
B8: Bar sales (from stock movement) | C8: ='Bar Stock & Sales'!I10 -> 11992 | D8: 10850 | E8: =C8-D8 -> 1142
B9: Less: cost of bar sales | C9: ='Bar Stock & Sales'!J10 -> 7664 | D9: 6950 | E9: =C9-D9 -> 714
B10: Less: operating expenses | C10: =C40 -> 3340 | D10: =D40 -> 3120 | E10: =C10-D10 -> 220
B11: Less: unexplained bar shortfall | C11: =MAX(0,-'Bar Stock & Sales'!E18) -> 572 | D11: 150 | E11: =C11-D11 -> 422
B12: NET PROFIT | C12: =C7+C8-C9-C10-C11 -> 5816 | D12: =D7+D8-D9-D10-D11 -> 6030 | E12: =C12-D12 -> -214
B14: 2. Key indicators | C14: Sep 2026 | D14: Aug 2026 | E14: Change
B15: Rent collected | C15: ='Rent Roll'!E11 -> 4000 | D15: 4900 | E15: =C15-D15 -> -900
B16: Rent collection rate | C16: =C15/C7 -> 0.74074074 | D16: =D15/D7 -> 0.90740741 | E16: =C16-D16 -> -0.16666667
B17: Rent owing at month end (all tenants) | C17: ='Rent Roll'!H11 -> 1900 | D17: 500 | E17: =C17-D17 -> 1400
B18: Bar gross margin | C18: =(C8-C9)/C8 -> 0.36090727 | D18: =(D8-D9)/D8 -> 0.359447 | E18: =C18-D18 -> 0.0014602669
B19: Bar shortfall as % of bar sales | C19: =C11/C8 -> 0.047698466 | D19: =D11/D8 -> 0.013824885 | E19: =C19-D19 -> 0.033873581
B21: 3. From profit to cash
B22: Net profit | C22: =C12 -> 5816
B23: Less: increase in rent owed (earned, not yet received) | C23: ='Rent Roll'!H11-'Rent Roll'!G11 -> 1400
B24: Less: stock bought but not yet sold | C24: ='Bar Stock & Sales'!L10-'Bar Stock & Sales'!J10 -> 604
B25: Cash movement for the month | C25: =C22-C23-C24 -> 3812
B26: Check against cash sheet | C26: =IF(ABS(C25-('Cash & Reconciliation'!C10-'Cash & Reconciliation'!C5))<0.5,"Agrees","CHECK") -> Agrees
B27: Closing balance per records, 30 Sept | C27: ='Cash & Reconciliation'!C10 -> 6812
B28: Closing balance per statements | C28: ='Cash & Reconciliation'!C12 -> 6780
B29: Reconciliation status | C29: ='Cash & Reconciliation'!C15 -> Reconciled
B31: 4. Operating expenses by category | C31: Sep 2026 | D31: Aug 2026 | E31: Change
B32: Electricity | C32: =SUMIFS(Expenses!$E$5:$E$14,Expenses!$C$5:$C$14,B32) -> 850 | D32: 800 | E32: =C32-D32 -> 50
B33: Water | C33: =SUMIFS(Expenses!$E$5:$E$14,Expenses!$C$5:$C$14,B33) -> 120 | D33: 120 | E33: =C33-D33 -> 0
B34: Wages | C34: =SUMIFS(Expenses!$E$5:$E$14,Expenses!$C$5:$C$14,B34) -> 1400 | D34: 1400 | E34: =C34-D34 -> 0
B35: Repairs | C35: =SUMIFS(Expenses!$E$5:$E$14,Expenses!$C$5:$C$14,B35) -> 430 | D35: 300 | E35: =C35-D35 -> 130
B36: Transport | C36: =SUMIFS(Expenses!$E$5:$E$14,Expenses!$C$5:$C$14,B36) -> 150 | D36: 150 | E36: =C36-D36 -> 0
B37: Security | C37: =SUMIFS(Expenses!$E$5:$E$14,Expenses!$C$5:$C$14,B37) -> 300 | D37: 300 | E37: =C37-D37 -> 0
B38: Other | C38: =SUMIFS(Expenses!$E$5:$E$14,Expenses!$C$5:$C$14,B38) -> 90 | D38: 50 | E38: =C38-D38 -> 40
B40: Total operating expenses | C40: =SUM(C32:C38) -> 3340 | D40: =SUM(D32:D38) -> 3120 | E40: =C40-D40 -> 220
B58: 5. Findings and recommendations
B59: ="1. Bar takings are K"&TEXT(C11,"#,##0")&" ("&TEXT(C19,"0.0%")&" of sales) below what the stock movement says was sold, up from K"&TEXT(D11,"#,##0")&" last month. That is about "&TEXT('Bar Stock & Sales'!E22,"0")&" bottles of lager. Recommendation: for two weeks, count stock weekly and match takings to sales every day before drawing conclusions. Breakages, free drinks and unrecorded credit are common causes." -> 1. Bar takings are K572 (4.8% of sales) below what the stock movement says was sold, up from K150 last month. That is about 26 bottles of lager. Recommendation: for two weeks, count stock weekly and match takings to sales every day before drawing conclusions. Breakages, free drinks and unrecorded credit are common causes.
B60: ="2. Rent collection fell from "&TEXT(D16,"0%")&" to "&TEXT(C16,"0%")&". "&INDEX('Rent Roll'!C5:C10,MATCH(MAX('Rent Roll'!H5:H10),'Rent Roll'!H5:H10,0))&" owes K"&TEXT(MAX('Rent Roll'!H5:H10),"#,##0")&" ("&INDEX('Rent Roll'!I5:I10,MATCH(MAX('Rent Roll'!H5:H10),'Rent Roll'!H5:H10,0))&" months). Recommendation: give written notice and agree a payment plan now; arrears are easiest to recover before they reach a third month." -> 2. Rent collection fell from 91% to 74%. Tenant E owes K1,500 (2 months). Recommendation: give written notice and agree a payment plan now; arrears are easiest to recover before they reach a third month.
B61: ="3. Profit is K"&TEXT(C12,"#,##0")&" but cash rose by only K"&TEXT(C25,"#,##0")&". K"&TEXT(C23,"#,##0")&" is rent not yet paid and K"&TEXT(C24,"#,##0")&" is stock bought but not yet sold. Recommendation: judge the business on profit and cash together, and do not spend profit that is still sitting in arrears or on the shelf." -> 3. Profit is K5,816 but cash rose by only K3,812. K1,400 is rent not yet paid and K604 is stock bought but not yet sold. Recommendation: judge the business on profit and cash together, and do not spend profit that is still sitting in arrears or on the shelf.
B63: 6. Basis and assumptions
...

Sheet Rent Roll
B1: Rent Roll: September 2026
B2: SAMPLE DATA: fictional business and figures, for demonstration only. Not a real client.
B4: Unit | C4: Tenant (fictional) | D4: Rent due (K) | E4: Paid (K) | F4: Balance, Sept (K) | G4: Brought forward (K) | H4: Total owing (K) | I4: Months owing | J4: Suggested action
B5: Room 1 | C5: Tenant A | D5: 900 | E5: 900 | F5: =D5-E5 -> 0 | G5: 0 | H5: =F5+G5 -> 0 | I5: =IF(H5=0,0,ROUNDUP(H5/D5,0)) -> 0 | J5: =IF(H5=0,"None",IF(I5>=2,"Written notice and payment plan now",IF(E5=0,"Call tenant this week","Agree a date for the balance"))) -> None
B6: Room 2 | C6: Tenant B | D6: 900 | E6: 900 | F6: =D6-E6 -> 0 | G6: 0 | H6: =F6+G6 -> 0 | I6: =IF(H6=0,0,ROUNDUP(H6/D6,0)) -> 0 | J6: =IF(H6=0,"None",IF(I6>=2,"Written notice and payment plan now",IF(E6=0,"Call tenant this week","Agree a date for the balance"))) -> None
B7: Room 3 | C7: Tenant C | D7: 800 | E7: 400 | F7: =D7-E7 -> 400 | G7: 0 | H7: =F7+G7 -> 400 | I7: =IF(H7=0,0,ROUNDUP(H7/D7,0)) -> 1 | J7: =IF(H7=0,"None",IF(I7>=2,"Written notice and payment plan now",IF(E7=0,"Call tenant this week","Agree a date for the balance"))) -> Agree a date for the balance
B8: Room 4 | C8: Tenant D | D8: 800 | E8: 800 | F8: =D8-E8 -> 0 | G8: 0 | H8: =F8+G8 -> 0 | I8: =IF(H8=0,0,ROUNDUP(H8/D8,0)) -> 0 | J8: =IF(H8=0,"None",IF(I8>=2,"Written notice and payment plan now",IF(E8=0,"Call tenant this week","Agree a date for the balance"))) -> None
B9: Room 5 | C9: Tenant E | D9: 1000 | E9: 0 | F9: =D9-E9 -> 1000 | G9: 500 | H9: =F9+G9 -> 1500 | I9: =IF(H9=0,0,ROUNDUP(H9/D9,0)) -> 2 | J9: =IF(H9=0,"None",IF(I9>=2,"Written notice and payment plan now",IF(E9=0,"Call tenant this week","Agree a date for the balance"))) -> Written notice and payment plan now
B10: Room 6 | C10: Tenant F | D10: 1000 | E10: 1000 | F10: =D10-E10 -> 0 | G10: 0 | H10: =F10+G10 -> 0 | I10: =IF(H10=0,0,ROUNDUP(H10/D10,0)) -> 0 | J10: =IF(H10=0,"None",IF(I10>=2,"Written notice and payment plan now",IF(E10=0,"Call tenant this week","Agree a date for the balance"))) -> None
B11: Total | D11: =SUM(D5:D10) -> 5400 | E11: =SUM(E5:E10) -> 4000 | F11: =SUM(F5:F10) -> 1400 | G11: =SUM(G5:G10) -> 500 | H11: =SUM(H5:H10) -> 1900 | J11: =TEXT(E11/D11,"0%")&" of Sept rent collected" -> 74% of Sept rent collected
B13: Brought forward = unpaid rent from August. Months owing = total owing divided by monthly rent, rounded up.

Sheet Bar Stock & Sales
B1: Bar Stock, Sales and Takings Check: September 2026
B2: SAMPLE DATA: fictional business and figures, for demonstration only. Not a real client.
B4: Item | C4: Opening stock | D4: Purchased | E4: Closing stock | F4: Units sold | G4: Cost price (K) | H4: Selling price (K) | I4: Sales (K) | J4: Cost of sales (K) | K4: Gross profit (K) | L4: Purchases (K)
B5: Lager (bottle) | C5: 48 | D5: 240 | E5: 60 | F5: =C5+D5-E5 -> 228 | G5: 14 | H5: 22 | I5: =F5*H5 -> 5016 | J5: =F5*G5 -> 3192 | K5: =I5-J5 -> 1824 | L5: =D5*G5 -> 3360
B6: Premium lager (bottle) | C6: 24 | D6: 120 | E6: 36 | F6: =C6+D6-E6 -> 108 | G6: 18 | H6: 28 | I6: =F6*H6 -> 3024 | J6: =F6*G6 -> 1944 | K6: =I6-J6 -> 1080 | L6: =D6*G6 -> 2160
B7: Soft drink (300ml) | C7: 36 | D7: 144 | E7: 48 | F7: =C7+D7-E7 -> 132 | G7: 6 | H7: 10 | I7: =F7*H7 -> 1320 | J7: =F7*G7 -> 792 | K7: =I7-J7 -> 528 | L7: =D7*G7 -> 864
B8: Bottled water (500ml) | C8: 30 | D8: 96 | E8: 42 | F8: =C8+D8-E8 -> 84 | G8: 4 | H8: 8 | I8: =F8*H8 -> 672 | J8: =F8*G8 -> 336 | K8: =I8-J8 -> 336 | L8: =D8*G8 -> 384
B9: Opaque beer (2L) | C9: 12 | D9: 60 | E9: 16 | F9: =C9+D9-E9 -> 56 | G9: 25 | H9: 35 | I9: =F9*H9 -> 1960 | J9: =F9*G9 -> 1400 | K9: =I9-J9 -> 560 | L9: =D9*G9 -> 1500
B10: Total | F10: =SUM(F5:F9) -> 608 | I10: =SUM(I5:I9) -> 11992 | J10: =SUM(J5:J9) -> 7664 | K10: =SUM(K5:K9) -> 4328 | L10: =SUM(L5:L9) -> 8268
B11: Units sold = opening + purchased - closing. Gross margin: | F11: =K10/I10 -> 0.36090727
B13: Takings check: does the money match the stock?
B14: Expected sales (from stock movement) | E14: =I10 -> 11992
B15: Cash takings recorded | E15: 6820
B16: Mobile money takings recorded | E16: 4600
B17: Total takings recorded | E17: =E15+E16 -> 11420
B18: Shortfall (-) or surplus (+) | E18: =E17-E14 -> -572
B19: Shortfall as % of expected sales | E19: =E18/E14 -> -0.047698466
B20: Tolerance allowed | E20: 0.02
B21: Result | E21: =IF(ABS(E19)<=E20,"Within tolerance","INVESTIGATE") -> INVESTIGATE
B22: Shortfall in bottles of lager (at selling price) | E22: =MAX(0,-E18)/H5 -> 26
B24: Common causes to check first: unrecorded credit sales, free or staff drinks, breakages, wrong prices charged, takings used before recording, miscounted stock.
B25: A shortfall is a question to ask, not proof of theft.

Sheet Expenses
B1: Expense Log: September 2026
B2: SAMPLE DATA: fictional business and figures, for demonstration only. Not a real client.
B4: Date | C4: Category | D4: Description | E4: Amount (K)
B5: 2026-09-02 | C5: Electricity | D5: Prepaid units | E5: 450
B6: 2026-09-03 | C6: Water | D6: Monthly bill | E6: 120
B7: 2026-09-05 | C7: Wages | D7: Bar attendant | E7: 900
B8: 2026-09-05 | C8: Wages | D8: Cleaner / caretaker | E8: 500
B9: 2026-09-09 | C9: Repairs | D9: Room 3 door lock | E9: 180
B10: 2026-09-12 | C10: Transport | D10: Stock collection | E10: 150
B11: 2026-09-15 | C11: Security | D11: Guard contribution | E11: 300
B12: 2026-09-18 | C12: Repairs | D12: Plumbing, shared bathroom | E12: 250
B13: 2026-09-24 | C13: Other | D13: Cleaning supplies | E13: 90
B14: 2026-09-28 | C14: Electricity | D14: Prepaid units | E14: 400
D15: Total | E15: =SUM(E5:E14) -> 3340

Sheet Cash & Reconciliation
B1: Cash and Reconciliation: September 2026
B2: SAMPLE DATA: fictional business and figures, for demonstration only. Not a real client.
B3: Cash = cash in hand + bank + mobile money (MTN / Airtel).
B5: Opening balance, 1 Sept (per records) | C5: 3000
B6: Add: rent collected | C6: ='Rent Roll'!E11 -> 4000
B7: Add: bar takings recorded | C7: ='Bar Stock & Sales'!E17 -> 11420
B8: Less: stock purchases | C8: =-'Bar Stock & Sales'!L10 -> -8268
B9: Less: operating expenses | C9: =-Expenses!E15 -> -3340
B10: Closing balance, 30 Sept (per records) | C10: =SUM(C5:C9) -> 6812
B12: Balance per bank / mobile money statements | C12: 6780
B13: Difference (statements minus records) | C13: =C12-C10 -> -32
B14: Tolerance allowed | C14: 50
B15: Status | C15: =IF(ABS(C13)<=C14,"Reconciled","INVESTIGATE") -> Reconciled
B17: A small difference like this is usually mobile money charges not yet entered. Anything above the tolerance is traced line by line before the report is issued.

Sheet Messy to Clean
B1: From Messy Notes to Clean Records
B2: SAMPLE DATA: fictional business and figures, for demonstration only. Not a real client.
B3: Fictional example of what a client sends, how it is entered, and what gets queried. Nothing is guessed silently.
B5: What the client sent (typed copy of a notebook) | C5: Entered in | D5: Entered as | E5: Status
B6: 5/9 lager 240 btl pd cash 3360 | C6: Bar: purchases | D6: Lager, 240 bottles, K3,360 | E6: Entered
B7: rm3 half rent 400 | C7: Rent Roll | D7: Room 3, paid K400, balance K400 | E7: Entered
B8: elec 400 28/9 | C8: Expenses | D8: 28 Sep, Electricity, K400 | E8: Entered
B9: door lock rm3 180 | C9: Expenses | D9: 9 Sep, Repairs, K180 | E9: Entered
B10: sat takings approx 1300?? mm + cash | C10: Bar: takings | D10: Not entered: amount unclear | E10: Query sent to client
B11: Rm5 will pay next wk | C11: Rent Roll | D11: Room 5, paid K0, noted promise to pay | E11: Follow up next month

Sheet About & Process
B1: About this Service
B2: SAMPLE DATA: fictional business and figures, for demonstration only. Not a real client.
B4: Prepared by | C4: Caristo Mulenga, CayTech Digital Solutions, Ndola, Zambia
B5: Qualifications, stated plainly | C5: ZICA Diploma in Accountancy (in progress). Two years of experience as an assistant accountant. I am not a qualified or registered accountant. This is bookkeeping and management reporting, not audit, tax or legal advice.
B6: What is included | C6: Monthly rent roll with arrears follow-up list; bar stock and takings check; expense log; cash reconciliation to your bank / mobile money statements; monthly report with plain-language findings.
B7: What is not included | C7: Audits, tax returns or ZRA filings, payroll statutory returns, legal advice. Payroll support can be quoted separately.
B8: Monthly timeline | C8: By the 3rd: you send records. By the 7th: I send you any questions. By the 10th: you receive the report.
B9: What I need from you | C9: Rent receipts, weekly stock counts, daily takings, supplier invoices and receipts, bank / mobile money statements. Photos of notebooks are fine.
B10: Price | C10: From K600 per month, depending on the number of units and the volume of records. A written quote is given before any work starts.
B11: Confidentiality | C11: Your records are used only to prepare your reports, are kept in password-protected files, and are not shared with anyone. On request, they are returned and deleted when we stop working together.
B12: Contact | C12: WhatsApp +260 963 149 074
